Workbook
Name ListaLokali: _xlfn._xlws.FILTER(TabelaLokale[Nr lokalu],TabelaLokale[Miasto]=Przeglądy!$A1)

Sheet Lokale
B2: Miasto | C2: Nr lokalu
B3: BYDGOSZCZ | C3: B75 (Multistore)
B4: BYDGOSZCZ | C4: B38 (Ministore)
B5: KATOWICE | C5: B52 (Multistore)
B6: KATOWICE | C6: B53 (Glamour)
B7: KATOWICE | C7: BA1 (Beauty Shop)
B8: KATOWICE | C8: BA2 (Multistore)
B9: KATOWICE | C9: B51 (Magazyn)
B10: KATOWICE | C10: 284 (Cavarious)
B11: POZNAŃ | C11: B39 (Multistore)
B12: POZNAŃ | C12: B17 (Ministore)
B13: POZNAŃ | C13: B15 (ZOOM)
... B74: KRAKÓW | C74: Wszystkie lokale

Sheet Listy
A1: Termin ważności | C1: Grupa przeglądu | D1: Rodzaj przeglądu
A2: 1 | C2: Główny | D2: Elektryczny (roczny)
A3: 2 | C3: Główny | D3: Elektryczny (5-cio letni)
A4: 3 | C4: Główny | D4: Systemy PPOŻ
A5: 6 | C5: Główny | D5: Gaśnice
A6: 12 | C6: Główny | D6: Klimatyzacja
A7: 24 | C7: Główny | D7: Alarmy
A8: 36 | C8: Główny | D8: Hydranty
A9: 60 | C9: Główny | D9: Rolety
C10: Główny | D10: Wentylacja
C11: Główny | D11: Wymiana filtrów
C12: Główny | D12: Regałów magazynowych
C13: Główny | D13: CRO
C14: Główny | D14: Mroźnia/Chłodnia
C15: Główny | D15: Regały chłodnicze
C16: Główny | D16: Separatory tłuszczu
C17: Główny | D17: Vendingi
C18: Główny | D18: UDT (wózki widłowe, paleciaki)
C19: Główny | D19: BHP (drabiny, schodki, podesty)
C20: Główny | D20: Ansul | E20: travel chef/ cavarious/ notam/poznań/katowice/radom x2 - travel chef i cavarious, treminal A katowice - centralna nawiewowa
C21: Główny | D21: Okap
C22: Główny | D22: Brama garażowa | E22: katowice magazyn - zew. Na płycie lotniska
C23: Główny | D23: Żaluzje (gastro)
C24: Główny | D24: Bramki antykradzieżowe
C25: Poboczny | D25: Klamki na kod
C26: Poboczny | D26: Oświetlenie
C27: Poboczny | D27: Drzwi przeciwpożarowe
C28: Poboczny | D28: Drzwi na zaplecze
C29: Poboczny | D29: Systemy multmedialne
C30: Poboczny | D30: Posadzki, wykładziny
C31: Poboczny | D31: Kontrola kurzu
C32: Poboczny | D32: Light boxy
C33: Poboczny | D33: Floorboxy
C34: Poboczny | D34: Meble
... C40: Poboczny | D40: Sprawdzenie pompy odpływowej

Sheet Pomoc
A1: Lista miast
A2: {=_xlfn.UNIQUE(TabelaLokale[Miasto])} -> BYDGOSZCZ
A3: KATOWICE
A4: POZNAŃ
A5: RZESZÓW
A6: WROCŁAW
A7: WARSZAWA
A8: SONATA
A9: WARSZAWA ZACHODNIA
A10: MODLIN
A11: RADOM
A12: KRAKÓW
A13: ŚWINOUJŚCIE
A14: ZIELONA GÓRA
A15: 0

Sheet Drabiny i podesty
B2: MPK (LOKAL) | C2: RODZAJ | D2: ILOŚĆ (szt.) | E2: ILOŚĆ SZCZEBLI
B3: B75/B38 Bygdoszcz | C3: Drabiny metalowe | D3: 1 | E3: 4
D4: 1 | E4: 5
C5: Podsest plastikowy | D5: 1 | E5: 42cm
B6: 532 Magazyn WAW | C6: Drabiny plastikowe | D6: 2 | E6: 2
C7: Drabiny metalowe | D7: 2 | E7: 3
D8: 1 | E8: 5
D9: 1 | E9: 7
D10: 3 | E10: 21
C11: Schodki | D11: 1 | E11: 9
B12: 288 (PKP Kraków) | C12: Drabina metalowa | D12: 1 | E12: 14
B13: 170 WAW | C13: Schodki plastikowe | D13: 1 | E13: 2
B14: 181 WAW | C14: Schodki plastikowe | D14: 1 | E14: 2
B15: 174 WAW | C15: Schodki plastikowe | D15: 1 | E15: 2
B16: 177 WAW | C16: Schodki plastikowe | D16: 2 | E16: 2
B17: 182 WAW | C17: Schodki plastikowe | D17: 1 | E17: 2
C18: Drabina metalowa | D18: 1 | E18: 5
B19: 171,172,180 | C19: Schodki plastikowe | D19: 1 | E19: 2
C20: Schodki metalowe | D20: 1 | E20: 2
B21: 183 WAW | C21: Schodki plastikowe | D21: 1 | E21: 2
C22: Drabina metalowa | D22: 1 | E22: 5

Sheet Przeglądy
A1: Miasto | B1: Nr lokalu | C1: Grupa przeglądu | D1: Rodzaj przeglądu | E1: Data wykonania | F1: Ważny przez (mies.) | G1: Data następnego przeglądu | H1: Status | I1: Data dodania protokołu | J1: Czy protokół dodany | K1: Uwagi
A2: RADOM | B2: 211 (Travel Chef) | C2: Główny | D2: Okap | E2: 46163 | F2: 12 | G2: =IF(OR(E2="",F2=""),"",DATE(YEAR(E2),MONTH(E2)+F2,DAY(E2))) -> 46528 | H2: =IF(G2="","",IF(G2<TODAY(),"PO TERMINIE",IF(G2<=TODAY()+14,"DO WYKONANIA","OK"))) -> OK | J2: =IF(COUNTA(A2:F2)=0,"",IF(I2="","BRAK PROTOKOŁU","DODANY")) -> BRAK PROTOKOŁU | M2: {=IF($A2="","",IFERROR(TRANSPOSE(_xlfn._xlws.FILTER(Lokale!$C$3:$C$91,Lokale!$B$3:$B$91=$A2)),""))} -> 212 (Cavarious) | N2: 211 (Travel Chef) | O2: 213 (Cavarious NS) | P2: BR1 (Multistore) | Q2: BR2 (ZOOM) | R2: BR3 (Ministore) | S2: 214 (Bistro) | T2: BR4 (Starter) | U2: Wszystkie lokale | AJ2: {=IF($C2="","",IFERROR(TRANSPOSE(_xlfn._xlws.FILTER(Listy!$D$2:$D$60,Listy!$C$2:$C$60=$C2)),""))} -> Elektryczny (roczny) | AK2: Elektryczny (5-cio letni) | AL2: Systemy PPOŻ | AM2: Gaśnice | AN2: Klimatyzacja | AO2: Alarmy | AP2: Hydranty | AQ2: Rolety | AR2: Wentylacja | AS2: Wymiana filtrów | AT2: Regałów magazynowych | AU2: CRO | AV2: Mroźnia/Chłodnia | AW2: Regały chłodnicze | AX2: Separatory tłuszczu | AY2: Vendingi | AZ2: UDT (wózki widłowe, paleciaki) | BA2: BHP (drabiny, schodki, podesty) | BB2: Ansul | BC2: Okap | BD2: Brama garażowa | BE2: Żaluzje (gastro) | BF2: Bramki antykradzieżowe | BG2: Mycie jednostek klimatyzacji
A3: RADOM | B3: 214 (Bistro) | C3: Główny | D3: Okap | E3: 46163 | F3: 12 | G3: =IF(OR(E3="",F3=""),"",DATE(YEAR(E3),MONTH(E3)+F3,DAY(E3))) -> 46528 | H3: =IF(G3="","",IF(G3<TODAY(),"PO TERMINIE",IF(G3<=TODAY()+14,"DO WYKONANIA","OK"))) -> OK | J3: =IF(COUNTA(A3:F3)=0,"",IF(I3="","BRAK PROTOKOŁU","DODANY")) -> BRAK PROTOKOŁU | M3: {=IF($A3="","",IFERROR(TRANSPOSE(_xlfn._xlws.FILTER(Lokale!$C$3:$C$91,Lokale!$B$3:$B$91=$A3)),""))} -> 212 (Cavarious) | N3: 211 (Travel Chef) | O3: 213 (Cavarious NS) | P3: BR1 (Multistore) | Q3: BR2 (ZOOM) | R3: BR3 (Ministore) | S3: 214 (Bistro) | T3: BR4 (Starter) | U3: Wszystkie lokale | AJ3: {=IF($C3="","",IFERROR(TRANSPOSE(_xlfn._xlws.FILTER(Listy!$D$2:$D$60,Listy!$C$2:$C$60=$C3)),""))} -> Elektryczny (roczny) | AK3: Elektryczny (5-cio letni) | AL3: Systemy PPOŻ | AM3: Gaśnice | AN3: Klimatyzacja | AO3: Alarmy | AP3: Hydranty | AQ3: Rolety | AR3: Wentylacja | AS3: Wymiana filtrów | AT3: Regałów magazynowych | AU3: CRO | AV3: Mroźnia/Chłodnia | AW3: Regały chłodnicze | AX3: Separatory tłuszczu | AY3: Vendingi | AZ3: UDT (wózki widłowe, paleciaki) | BA3: BHP (drabiny, schodki, podesty) | BB3: Ansul | BC3: Okap | BD3: Brama garażowa | BE3: Żaluzje (gastro) | BF3: Bramki antykradzieżowe | BG3: Mycie jednostek klimatyzacji
A4: SONATA | B4: 210 (NOTAM) | C4: Główny | D4: Okap | E4: 46091 | F4: 12 | G4: =IF(OR(E4="",F4=""),"",DATE(YEAR(E4),MONTH(E4)+F4,DAY(E4))) -> 46456 | H4: =IF(G4="","",IF(G4<TODAY(),"PO TERMINIE",IF(G4<=TODAY()+14,"DO WYKONANIA","OK"))) -> OK | J4: =IF(COUNTA(A4:F4)=0,"",IF(I4="","BRAK PROTOKOŁU","DODANY")) -> BRAK PROTOKOŁU | M4: {=IF($A4="","",IFERROR(TRANSPOSE(_xlfn._xlws.FILTER(Lokale!$C$3:$C$91,Lokale!$B$3:$B$91=$A4)),""))} -> 210 (NOTAM) | AJ4: {=IF($C4="","",IFERROR(TRANSPOSE(_xlfn._xlws.FILTER(Listy!$D$2:$D$60,Listy!$C$2:$C$60=$C4)),""))} -> Elektryczny (roczny) | AK4: Elektryczny (5-cio letni) | AL4: Systemy PPOŻ | AM4: Gaśnice | AN4: Klimatyzacja | AO4: Alarmy | AP4: Hydranty | AQ4: Rolety | AR4: Wentylacja | AS4: Wymiana filtrów | AT4: Regałów magazynowych | AU4: CRO | AV4: Mroźnia/Chłodnia | AW4: Regały chłodnicze | AX4: Separatory tłuszczu | AY4: Vendingi | AZ4: UDT (wózki widłowe, paleciaki) | BA4: BHP (drabiny, schodki, podesty) | BB4: Ansul | BC4: Okap | BD4: Brama garażowa | BE4: Żaluzje (gastro) | BF4: Bramki antykradzieżowe | BG4: Mycie jednostek klimatyzacji
A5: RADOM | B5: 212 (Cavarious) | C5: Główny | D5: Okap | E5: 46168 | F5: 12 | G5: =IF(OR(E5="",F5=""),"",DATE(YEAR(E5),MONTH(E5)+F5,DAY(E5))) -> 46533 | H5: =IF(G5="","",IF(G5<TODAY(),"PO TERMINIE",IF(G5<=TODAY()+14,"DO WYKONANIA","OK"))) -> OK | M5: {=IF($A5="","",IFERROR(TRANSPOSE(_xlfn._xlws.FILTER(Lokale!$C$3:$C$91,Lokale!$B$3:$B$91=$A5)),""))} -> 212 (Cavarious) | N5: 211 (Travel Chef) | O5: 213 (Cavarious NS) | P5: BR1 (Multistore) | Q5: BR2 (ZOOM) | R5: BR3 (Ministore) | S5: 214 (Bistro) | T5: BR4 (Starter) | U5: Wszystkie lokale
A6: ŚWINOUJŚCIE | B6: B76 | C6: Główny | D6: Alarmy | E6: 46154 | F6: 12 | G6: =IF(OR(E6="",F6=""),"",DATE(YEAR(E6),MONTH(E6)+F6,DAY(E6))) -> 46519 | H6: =IF(G6="","",IF(G6<TODAY(),"PO TERMINIE",IF(G6<=TODAY()+14,"DO WYKONANIA","OK"))) -> OK | J6: =IF(COUNTA(A6:F6)=0,"",IF(I6="","BRAK PROTOKOŁU","DODANY")) -> BRAK PROTOKOŁU | M6: {=IF($A6="","",IFERROR(TRANSPOSE(_xlfn._xlws.FILTER(Lokale!$C$3:$C$91,Lokale!$B$3:$B$91=$A6)),""))} -> B76 | AJ6: {=IF($C6="","",IFERROR(TRANSPOSE(_xlfn._xlws.FILTER(Listy!$D$2:$D$60,Listy!$C$2:$C$60=$C6)),""))} -> Elektryczny (roczny) | AK6: Elektryczny (5-cio letni) | AL6: Systemy PPOŻ | AM6: Gaśnice | AN6: Klimatyzacja | AO6: Alarmy | AP6: Hydranty | AQ6: Rolety | AR6: Wentylacja | AS6: Wymiana filtrów | AT6: Regałów magazynowych | AU6: CRO | AV6: Mroźnia/Chłodnia | AW6: Regały chłodnicze | AX6: Separatory tłuszczu | AY6: Vendingi | AZ6: UDT (wózki widłowe, paleciaki) | BA6: BHP (drabiny, schodki, podesty) | BB6: Ansul | BC6: Okap | BD6: Brama garażowa | BE6: Żaluzje (gastro) | BF6: Bramki antykradzieżowe | BG6: Mycie jednostek klimatyzacji
A7: KRAKÓW | B7: BK1 (Magazyn) | C7: Główny | D7: UDT (wózki widłowe, paleciaki) | E7: 46154 | F7: 12 | G7: =IF(OR(E7="",F7=""),"",DATE(YEAR(E7),MONTH(E7)+F7,DAY(E7))) -> 46519 | H7: =IF(G7="","",IF(G7<TODAY(),"PO TERMINIE",IF(G7<=TODAY()+14,"DO WYKONANIA","OK"))) -> OK | J7: =IF(COUNTA(A7:F7)=0,"",IF(I7="","BRAK PROTOKOŁU","DODANY")) -> BRAK PROTOKOŁU | K7: Nr seryjny - N9712003189 | M7: {=IF($A7="","",IFERROR(TRANSPOSE(_xlfn._xlws.FILTER(Lokale!$C$3:$C$91,Lokale!$B$3:$B$91=$A7)),""))} -> BK3 (Ministore) | N7: BK4 (Ministore NS) | O7: BK2 (Multistore) | P7: BK1 (Magazyn) | Q7: 288 (Dworzec PKP) | R7: Wszystkie lokale | AJ7: {=IF($C7="","",IFERROR(TRANSPOSE(_xlfn._xlws.FILTER(Listy!$D$2:$D$60,Listy!$C$2:$C$60=$C7)),""))} -> Elektryczny (roczny) | AK7: Elektryczny (5-cio letni) | AL7: Systemy PPOŻ | AM7: Gaśnice | AN7: Klimatyzacja | AO7: Alarmy | AP7: Hydranty | AQ7: Rolety | AR7: Wentylacja | AS7: Wymiana filtrów | AT7: Regałów magazynowych | AU7: CRO | AV7: Mroźnia/Chłodnia | AW7: Regały chłodnicze | AX7: Separatory tłuszczu | AY7: Vendingi | AZ7: UDT (wózki widłowe, paleciaki) | BA7: BHP (drabiny, schodki, podesty) | BB7: Ansul | BC7: Okap | BD7: Brama garażowa | BE7: Żaluzje (gastro) | BF7: Bramki antykradzieżowe | BG7: Mycie jednostek klimatyzacji
A8: KRAKÓW | B8: BK1 (Magazyn) | C8: Główny | D8: UDT (wózki widłowe, paleciaki) | E8: 46154 | F8: 12 | G8: =IF(OR(E8="",F8=""),"",DATE(YEAR(E8),MONTH(E8)+F8,DAY(E8))) -> 46519 | H8: =IF(G8="","",IF(G8<TODAY(),"PO TERMINIE",IF(G8<=TODAY()+14,"DO WYKONANIA","OK"))) -> OK | J8: =IF(COUNTA(A8:F8)=0,"",IF(I8="","BRAK PROTOKOŁU","DODANY")) -> BRAK PROTOKOŁU | K8: Nr seryjny - N9712003188 | M8: {=IF($A8="","",IFERROR(TRANSPOSE(_xlfn._xlws.FILTER(Lokale!$C$3:$C$91,Lokale!$B$3:$B$91=$A8)),""))} -> BK3 (Ministore) | N8: BK4 (Ministore NS) | O8: BK2 (Multistore) | P8: BK1 (Magazyn) | Q8: 288 (Dworzec PKP) | R8: Wszystkie lokale | AJ8: {=IF($C8="","",IFERROR(TRANSPOSE(_xlfn._xlws.FILTER(Listy!$D$2:$D$60,Listy!$C$2:$C$60=$C8)),""))} -> Elektryczny (roczny) | AK8: Elektryczny (5-cio letni) | AL8: Systemy PPOŻ | AM8: Gaśnice | AN8: Klimatyzacja | AO8: Alarmy | AP8: Hydranty | AQ8: Rolety | AR8: Wentylacja | AS8: Wymiana filtrów | AT8: Regałów magazynowych | AU8: CRO | AV8: Mroźnia/Chłodnia | AW8: Regały chłodnicze | AX8: Separatory tłuszczu | AY8: Vendingi | AZ8: UDT (wózki widłowe, paleciaki) | BA8: BHP (drabiny, schodki, podesty) | BB8: Ansul | BC8: Okap | BD8: Brama garażowa | BE8: Żaluzje (gastro) | BF8: Bramki antykradzieżowe | BG8: Mycie jednostek klimatyzacji
A9: WARSZAWA | B9: 532 (Magazyn) | C9: Główny | D9: UDT (wózki widłowe, paleciaki) | E9: 46155 | F9: 12 | G9: =IF(OR(E9="",F9=""),"",DATE(YEAR(E9),MONTH(E9)+F9,DAY(E9))) -> 46520 | H9: =IF(G9="","",IF(G9<TODAY(),"PO TERMINIE",IF(G9<=TODAY()+14,"DO WYKONANIA","OK"))) -> OK | J9: =IF(COUNTA(A9:F9)=0,"",IF(I9="","BRAK PROTOKOŁU","DODANY")) -> BRAK PROTOKOŁU | K9: AMC 12, Nr seryjny - N21062048096 | M9: {=IF($A9="","",IFERROR(TRANSPOSE(_xlfn._xlws.FILTER(Lokale!$C$3:$C$91,Lokale!$B$3:$B$91=$A9)),""))} -> 170 (Glamour) | N9: 171 (Starter Dworzec) | O9: 172 (Starter Przyloty) | P9: 173 (LMDL2) | Q9: 174 (Zoom NS) | R9: 175 (Ministore NS) | S9: 176 (Zoom odloty) | T9: 177 (Spirit of Poland) | U9: 178 (Multistore) | V9: 179 (ZOOM) | W9: 180 (Starter odloty) | X9: 181 (Bestseller) | Y9: 182 (Zoom palarnia) | Z9: 183 (LMDL) | AA9: 187 (Zoom NS) | AB9: 208 (PIZZA) | AC9: 532 (Magazyn) | AD9: Wszystkie lokale | AJ9: {=IF($C9="","",IFERROR(TRANSPOSE(_xlfn._xlws.FILTER(Listy!$D$2:$D$60,Listy!$C$2:$C$60=$C9)),""))} -> Elektryczny (roczny) | AK9: Elektryczny (5-cio letni) | AL9: Systemy PPOŻ | AM9: Gaśnice | AN9: Klimatyzacja | AO9: Alarmy | AP9: Hydranty | AQ9: Rolety | AR9: Wentylacja | AS9: Wymiana filtrów | AT9: Regałów magazynowych | AU9: CRO | AV9: Mroźnia/Chłodnia | AW9: Regały chłodnicze | AX9: Separatory tłuszczu | AY9: Vendingi | AZ9: UDT (wózki widłowe, paleciaki) | BA9: BHP (drabiny, schodki, podesty) | BB9: Ansul | BC9: Okap | BD9: Brama garażowa | BE9: Żaluzje (gastro) | BF9: Bramki antykradzieżowe | BG9: Mycie jednostek klimatyzacji
A10: KATOWICE | B10: B51 (Magazyn) | C10: Główny | D10: UDT (wózki widłowe, paleciaki) | E10: 46076 | F10: 12 | G10: =IF(OR(E10="",F10=""),"",DATE(YEAR(E10),MONTH(E10)+F10,DAY(E10))) -> 46441 | H10: =IF(G10="","",IF(G10<TODAY(),"PO TERMINIE",IF(G10<=TODAY()+14,"DO WYKONANIA","OK"))) -> OK | J10: =IF(COUNTA(A10:F10)=0,"",IF(I10="","BRAK PROTOKOŁU","DODANY")) -> BRAK PROTOKOŁU | K10: Samochód - WW392GU | M10: {=IF($A10="","",IFERROR(TRANSPOSE(_xlfn._xlws.FILTER(Lokale!$C$3:$C$91,Lokale!$B$3:$B$91=$A10)),""))} -> B52 (Multistore) | N10: B53 (Glamour) | O10: BA1 (Beauty Shop) | P10: BA2 (Multistore) | Q10: B51 (Magazyn) | R10: 284 (Cavarious) | S10: Wszystkie lokale | AJ10: {=IF($C10="","",IFERROR(TRANSPOSE(_xlfn._xlws.FILTER(Listy!$D$2:$D$60,Listy!$C$2:$C$60=$C10)),""))} -> Elektryczny (roczny) | AK10: Elektryczny (5-cio letni) | AL10: Systemy PPOŻ | AM10: Gaśnice | AN10: Klimatyzacja | AO10: Alarmy | AP10: Hydranty | AQ10: Rolety | AR10: Wentylacja | AS10: Wymiana filtrów | AT10: Regałów magazynowych | AU10: CRO | AV10: Mroźnia/Chłodnia | AW10: Regały chłodnicze | AX10: Separatory tłuszczu | AY10: Vendingi | AZ10: UDT (wózki widłowe, paleciaki) | BA10: BHP (drabiny, schodki, podesty) | BB10: Ansul | BC10: Okap | BD10: Brama garażowa | BE10: Żaluzje (gastro) | BF10: Bramki antykradzieżowe | BG10: Mycie jednostek klimatyzacji
A11: KRAKÓW | B11: BK1 (Magazyn) | C11: Główny | D11: UDT (wózki widłowe, paleciaki) | E11: 46104 | F11: 12 | G11: =IF(OR(E11="",F11=""),"",DATE(YEAR(E11),MONTH(E11)+F11,DAY(E11))) -> 46469 | H11: =IF(G11="","",IF(G11<TODAY(),"PO TERMINIE",IF(G11<=TODAY()+14,"DO WYKONANIA","OK"))) -> OK | J11: =IF(COUNTA(A11:F11)=0,"",IF(I11="","BRAK PROTOKOŁU","DODANY")) -> BRAK PROTOKOŁU | K11: Samochód - WW390GU | M11: {=IF($A11="","",IFERROR(TRANSPOSE(_xlfn._xlws.FILTER(Lokale!$C$3:$C$91,Lokale!$B$3:$B$91=$A11)),""))} -> BK3 (Ministore) | N11: BK4 (Ministore NS) | O11: BK2 (Multistore) | P11: BK1 (Magazyn) | Q11: 288 (Dworzec PKP) | R11: Wszystkie lokale | AJ11: {=IF($C11="","",IFERROR(TRANSPOSE(_xlfn._xlws.FILTER(Listy!$D$2:$D$60,Listy!$C$2:$C$60=$C11)),""))} -> Elektryczny (roczny) | AK11: Elektryczny (5-cio letni) | AL11: Systemy PPOŻ | AM11: Gaśnice | AN11: Klimatyzacja | AO11: Alarmy | AP11: Hydranty | AQ11: Rolety | AR11: Wentylacja | AS11: Wymiana filtrów | AT11: Regałów magazynowych | AU11: CRO | AV11: Mroźnia/Chłodnia | AW11: Regały chłodnicze | AX11: Separatory tłuszczu | AY11: Vendingi | AZ11: UDT (wózki widłowe, paleciaki) | BA11: BHP (drabiny, schodki, podesty) | BB11: Ansul | BC11: Okap | BD11: Brama garażowa | BE11: Żaluzje (gastro) | BF11: Bramki antykradzieżowe | BG11: Mycie jednostek klimatyzacji
A12: KRAKÓW | B12: BK1 (Magazyn) | C12: Główny | D12: UDT (wózki widłowe, paleciaki) | E12: 46070 | F12: 12 | G12: =IF(OR(E12="",F12=""),"",DATE(YEAR(E12),MONTH(E12)+F12,DAY(E12))) -> 46435 | H12: =IF(G12="","",IF(G12<TODAY(),"PO TERMINIE",IF(G12<=TODAY()+14,"DO WYKONANIA","OK"))) -> OK | J12: =IF(COUNTA(A12:F12)=0,"",IF(I12="","BRAK PROTOKOŁU","DODANY")) -> BRAK PROTOKOŁU | K12: Samochód - WW391GU | M12: {=IF($A12="","",IFERROR(TRANSPOSE(_xlfn._xlws.FILTER(Lokale!$C$3:$C$91,Lokale!$B$3:$B$91=$A12)),""))} -> BK3 (Ministore) | N12: BK4 (Ministore NS) | O12: BK2 (Multistore) | P12: BK1 (Magazyn) | Q12: 288 (Dworzec PKP) | R12: Wszystkie lokale | AJ12: {=IF($C12="","",IFERROR(TRANSPOSE(_xlfn._xlws.FILTER(Listy!$D$2:$D$60,Listy!$C$2:$C$60=$C12)),""))} -> Elektryczny (roczny) | AK12: Elektryczny (5-cio letni) | AL12: Systemy PPOŻ | AM12: Gaśnice | AN12: Klimatyzacja | AO12: Alarmy | AP12: Hydranty | AQ12: Rolety | AR12: Wentylacja | AS12: Wymiana filtrów | AT12: Regałów magazynowych | AU12: CRO | AV12: Mroźnia/Chłodnia | AW12: Regały chłodnicze | AX12: Separatory tłuszczu | AY12: Vendingi | AZ12: UDT (wózki widłowe, paleciaki) | BA12: BHP (drabiny, schodki, podesty) | BB12: Ansul | BC12: Okap | BD12: Brama garażowa | BE12: Żaluzje (gastro) | BF12: Bramki antykradzieżowe | BG12: Mycie jednostek klimatyzacji
A13: RADOM | B13: 212 (Cavarious) | C13: Główny | D13: Elektryczny (5-cio letni) | E13: 45568 | F13: 60 | G13: =IF(OR(E13="",F13=""),"",DATE(YEAR(E13),MONTH(E13)+F13,DAY(E13))) -> 47394 | H13: =IF(G13="","",IF(G13<TODAY(),"PO TERMINIE",IF(G13<=TODAY()+14,"DO WYKONANIA","OK"))) -> OK | J13: =IF(COUNTA(A13:F13)=0,"",IF(I13="","BRAK PROTOKOŁU","DODANY")) -> BRAK PROTOKOŁU | M13: {=IF($A13="","",IFERROR(TRANSPOSE(_xlfn._xlws.FILTER(Lokale!$C$3:$C$91,Lokale!$B$3:$B$91=$A13)),""))} -> 212 (Cavarious) | N13: 211 (Travel Chef) | O13: 213 (Cavarious NS) | P13: BR1 (Multistore) | Q13: BR2 (ZOOM) | R13: BR3 (Ministore) | S13: 214 (Bistro) | T13: BR4 (Starter) | U13: Wszystkie lokale | AJ13: {=IF($C13="","",IFERROR(TRANSPOSE(_xlfn._xlws.FILTER(Listy!$D$2:$D$60,Listy!$C$2:$C$60=$C13)),""))} -> Elektryczny (roczny) | AK13: Elektryczny (5-cio letni) | AL13: Systemy PPOŻ | AM13: Gaśnice | AN13: Klimatyzacja | AO13: Alarmy | AP13: Hydranty | AQ13: Rolety | AR13: Wentylacja | AS13: Wymiana filtrów | AT13: Regałów magazynowych | AU13: CRO | AV13: Mroźnia/Chłodnia | AW13: Regały chłodnicze | AX13: Separatory tłuszczu | AY13: Vendingi | AZ13: UDT (wózki widłowe, paleciaki) | BA13: BHP (drabiny, schodki, podesty) | BB13: Ansul | BC13: Okap | BD13: Brama garażowa | BE13: Żaluzje (gastro) | BF13: Bramki antykradzieżowe | BG13: Mycie jednostek klimatyzacji
A14: RADOM | B14: BR1 (Multistore) | C14: Główny | D14: Elektryczny (5-cio letni) | E14: 45568 | F14: 60 | G14: =IF(OR(E14="",F14=""),"",DATE(YEAR(E14),MONTH(E14)+F14,DAY(E14))) -> 47394 | H14: =IF(G14="","",IF(G14<TODAY(),"PO TERMINIE",IF(G14<=TODAY()+14,"DO WYKONANIA","OK"))) -> OK | J14: =IF(COUNTA(A14:F14)=0,"",IF(I14="","BRAK PROTOKOŁU","DODANY")) -> BRAK PROTOKOŁU | M14: {=IF($A14="","",IFERROR(TRANSPOSE(_xlfn._xlws.FILTER(Lokale!$C$3:$C$91,Lokale!$B$3:$B$91=$A14)),""))} -> 212 (Cavarious) | N14: 211 (Travel Chef) | O14: 213 (Cavarious NS) | P14: BR1 (Multistore) | Q14: BR2 (ZOOM) | R14: BR3 (Ministore) | S14: 214 (Bistro) | T14: BR4 (Starter) | U14: Wszystkie lokale | AJ14: {=IF($C14="","",IFERROR(TRANSPOSE(_xlfn._xlws.FILTER(Listy!$D$2:$D$60,Listy!$C$2:$C$60=$C14)),""))} -> Elektryczny (roczny) | AK14: Elektryczny (5-cio letni) | AL14: Systemy PPOŻ | AM14: Gaśnice | AN14: Klimatyzacja | AO14: Alarmy | AP14: Hydranty | AQ14: Rolety | AR14: Wentylacja | AS14: Wymiana filtrów | AT14: Regałów magazynowych | AU14: CRO | AV14: Mroźnia/Chłodnia | AW14: Regały chłodnicze | AX14: Separatory tłuszczu | AY14: Vendingi | AZ14: UDT (wózki widłowe, paleciaki) | BA14: BHP (drabiny, schodki, podesty) | BB14: Ansul | BC14: Okap | BD14: Brama garażowa | BE14: Żaluzje (gastro) | BF14: Bramki antykradzieżowe | BG14: Mycie jednostek klimatyzacji
A15: RADOM | B15: BR2 (ZOOM) | C15: Główny | D15: Elektryczny (5-cio letni) | E15: 45568 | F15: 60 | G15: =IF(OR(E15="",F15=""),"",DATE(YEAR(E15),MONTH(E15)+F15,DAY(E15))) -> 47394 | H15: =IF(G15="","",IF(G15<TODAY(),"PO TERMINIE",IF(G15<=TODAY()+14,"DO WYKONANIA","OK"))) -> OK | J15: =IF(COUNTA(A15:F15)=0,"",IF(I15="","BRAK PROTOKOŁU","DODANY")) -> BRAK PROTOKOŁU | M15: {=IF($A15="","",IFERROR(TRANSPOSE(_xlfn._xlws.FILTER(Lokale!$C$3:$C$91,Lokale!$B$3:$B$91=$A15)),""))} -> 212 (Cavarious) | N15: 211 (Travel Chef) | O15: 213 (Cavarious NS) | P15: BR1 (Multistore) | Q15: BR2 (ZOOM) | R15: BR3 (Ministore) | S15: 214 (Bistro) | T15: BR4 (Starter) | U15: Wszystkie lokale | AJ15: {=IF($C15="","",IFERROR(TRANSPOSE(_xlfn._xlws.FILTER(Listy!$D$2:$D$60,Listy!$C$2:$C$60=$C15)),""))} -> Elektryczny (roczny) | AK15: Elektryczny (5-cio letni) | AL15: Systemy PPOŻ | AM15: Gaśnice | AN15: Klimatyzacja | AO15: Alarmy | AP15: Hydranty | AQ15: Rolety | AR15: Wentylacja | AS15: Wymiana filtrów | AT15: Regałów magazynowych | AU15: CRO | AV15: Mroźnia/Chłodnia | AW15: Regały chłodnicze | AX15: Separatory tłuszczu | AY15: Vendingi | AZ15: UDT (wózki widłowe, paleciaki) | BA15: BHP (drabiny, schodki, podesty) | BB15: Ansul | BC15: Okap | BD15: Brama garażowa | BE15: Żaluzje (gastro) | BF15: Bramki antykradzieżowe | BG15: Mycie jednostek klimatyzacji
A16: RADOM | B16: BR3 (Ministore) | C16: Główny | D16: Elektryczny (5-cio letni) | E16: 45568 | F16: 60 | G16: =IF(OR(E16="",F16=""),"",DATE(YEAR(E16),MONTH(E16)+F16,DAY(E16))) -> 47394 | H16: =IF(G16="","",IF(G16<TODAY(),"PO TERMINIE",IF(G16<=TODAY()+14,"DO WYKONANIA","OK"))) -> OK | J16: =IF(COUNTA(A16:F16)=0,"",IF(I16="","BRAK PROTOKOŁU","DODANY")) -> BRAK PROTOKOŁU | M16: {=IF($A16="","",IFERROR(TRANSPOSE(_xlfn._xlws.FILTER(Lokale!$C$3:$C$91,Lokale!$B$3:$B$91=$A16)),""))} -> 212 (Cavarious) | N16: 211 (Travel Chef) | O16: 213 (Cavarious NS) | P16: BR1 (Multistore) | Q16: BR2 (ZOOM) | R16: BR3 (Ministore) | S16: 214 (Bistro) | T16: BR4 (Starter) | U16: Wszystkie lokale | AJ16: {=IF($C16="","",IFERROR(TRANSPOSE(_xlfn._xlws.FILTER(Listy!$D$2:$D$60,Listy!$C$2:$C$60=$C16)),""))} -> Elektryczny (roczny) | AK16: Elektryczny (5-cio letni) | AL16: Systemy PPOŻ | AM16: Gaśnice | AN16: Klimatyzacja | AO16: Alarmy | AP16: Hydranty | AQ16: Rolety | AR16: Wentylacja | AS16: Wymiana filtrów | AT16: Regałów magazynowych | AU16: CRO | AV16: Mroźnia/Chłodnia | AW16: Regały chłodnicze | AX16: Separatory tłuszczu | AY16: Vendingi | AZ16: UDT (wózki widłowe, paleciaki) | BA16: BHP (drabiny, schodki, podesty) | BB16: Ansul | BC16: Okap | BD16: Brama garażowa | BE16: Żaluzje (gastro) | BF16: Bramki antykradzieżowe | BG16: Mycie jednostek klimatyzacji
A17: RADOM | B17: 211 (Travel Chef) | C17: Główny | D17: Elektryczny (5-cio letni) | E17: 45568 | F17: 60 | G17: =IF(OR(E17="",F17=""),"",DATE(YEAR(E17),MONTH(E17)+F17,DAY(E17))) -> 47394 | H17: =IF(G17="","",IF(G17<TODAY(),"PO TERMINIE",IF(G17<=TODAY()+14,"DO WYKONANIA","OK"))) -> OK | J17: =IF(COUNTA(A17:F17)=0,"",IF(I17="","BRAK PROTOKOŁU","DODANY")) -> BRAK PROTOKOŁU | M17: {=IF($A17="","",IFERROR(TRANSPOSE(_xlfn._xlws.FILTER(Lokale!$C$3:$C$91,Lokale!$B$3:$B$91=$A17)),""))} -> 212 (Cavarious) | N17: 211 (Travel Chef) | O17: 213 (Cavarious NS) | P17: BR1 (Multistore) | Q17: BR2 (ZOOM) | R17: BR3 (Ministore) | S17: 214 (Bistro) | T17: BR4 (Starter) | U17: Wszystkie lokale | AJ17: {=IF($C17="","",IFERROR(TRANSPOSE(_xlfn._xlws.FILTER(Listy!$D$2:$D$60,Listy!$C$2:$C$60=$C17)),""))} -> Elektryczny (roczny) | AK17: Elektryczny (5-cio letni) | AL17: Systemy PPOŻ | AM17: Gaśnice | AN17: Klimatyzacja | AO17: Alarmy | AP17: Hydranty | AQ17: Rolety | AR17: Wentylacja | AS17: Wymiana filtrów | AT17: Regałów magazynowych | AU17: CRO | AV17: Mroźnia/Chłodnia | AW17: Regały chłodnicze | AX17: Separatory tłuszczu | AY17: Vendingi | AZ17: UDT (wózki widłowe, paleciaki) | BA17: BHP (drabiny, schodki, podesty) | BB17: Ansul | BC17: Okap | BD17: Brama garażowa | BE17: Żaluzje (gastro) | BF17: Bramki antykradzieżowe | BG17: Mycie jednostek klimatyzacji
A18: RADOM | B18: BR4 (Starter) | C18: Główny | D18: Elektryczny (5-cio letni) | E18: 45568 | F18: 60 | G18: =IF(OR(E18="",F18=""),"",DATE(YEAR(E18),MONTH(E18)+F18,DAY(E18))) -> 47394 | H18: =IF(G18="","",IF(G18<TODAY(),"PO TERMINIE",IF(G18<=TODAY()+14,"DO WYKONANIA","OK"))) -> OK | J18: =IF(COUNTA(A18:F18)=0,"",IF(I18="","BRAK PROTOKOŁU","DODANY")) -> BRAK PROTOKOŁU | M18: {=IF($A18="","",IFERROR(TRANSPOSE(_xlfn._xlws.FILTER(Lokale!$C$3:$C$91,Lokale!$B$3:$B$91=$A18)),""))} -> 212 (Cavarious) | N18: 211 (Travel Chef) | O18: 213 (Cavarious NS) | P18: BR1 (Multistore) | Q18: BR2 (ZOOM) | R18: BR3 (Ministore) | S18: 214 (Bistro) | T18: BR4 (Starter) | U18: Wszystkie lokale | AJ18: {=IF($C18="","",IFERROR(TRANSPOSE(_xlfn._xlws.FILTER(Listy!$D$2:$D$60,Listy!$C$2:$C$60=$C18)),""))} -> Elektryczny (roczny) | AK18: Elektryczny (5-cio letni) | AL18: Systemy PPOŻ | AM18: Gaśnice | AN18: Klimatyzacja | AO18: Alarmy | AP18: Hydranty | AQ18: Rolety | AR18: Wentylacja | AS18: Wymiana filtrów | AT18: Regałów magazynowych | AU18: CRO | AV18: Mroźnia/Chłodnia | AW18: Regały chłodnicze | AX18: Separatory tłuszczu | AY18: Vendingi | AZ18: UDT (wózki widłowe, paleciaki) | BA18: BHP (drabiny, schodki, podesty) | BB18: Ansul | BC18: Okap | BD18: Brama garażowa | BE18: Żaluzje (gastro) | BF18: Bramki antykradzieżowe | BG18: Mycie jednostek klimatyzacji
G19: =IF(OR(E19="",F19=""),"",DATE(YEAR(E19),MONTH(E19)+F19,DAY(E19))) | H19: =IF(G19="","",IF(G19<TODAY(),"PO TERMINIE",IF(G19<=TODAY()+14,"DO WYKONANIA","OK"))) | J19: =IF(COUNTA(A19:F183)=0,"",IF(#REF!="","BRAK PROTOKOŁU","DODANY")) -> #REF! | M19: {=IF($A19="","",IFERROR(TRANSPOSE(_xlfn._xlws.FILTER(Lokale!$C$3:$C$91,Lokale!$B$3:$B$91=$A19)),""))} | AJ19: {=IF($C19="","",IFERROR(TRANSPOSE(_xlfn._xlws.FILTER(Listy!$D$2:$D$60,Listy!$C$2:$C$60=$C19)),""))}
A20: WARSZAWA | B20: 208 (PIZZA) | C20: Główny | D20: Elektryczny (roczny) | E20: 46162 | F20: 12 | G20: =IF(OR(E20="",F20=""),"",DATE(YEAR(E20),MONTH(E20)+F20,DAY(E20))) -> 46527 | H20: =IF(G20="","",IF(G20<TODAY(),"PO TERMINIE",IF(G20<=TODAY()+14,"DO WYKONANIA","OK"))) -> OK | J20: =IF(COUNTA(A20:F183)=0,"",IF(#REF!="","BRAK PROTOKOŁU","DODANY")) -> #REF! | M20: {=IF($A20="","",IFERROR(TRANSPOSE(_xlfn._xlws.FILTER(Lokale!$C$3:$C$91,Lokale!$B$3:$B$91=$A20)),""))} -> 170 (Glamour) | N20: 171 (Starter Dworzec) | O20: 172 (Starter Przyloty) | P20: 173 (LMDL2) | Q20: 174 (Zoom NS) | R20: 175 (Ministore NS) | S20: 176 (Zoom odloty) | T20: 177 (Spirit of Poland) | U20: 178 (Multistore) | V20: 179 (ZOOM) | W20: 180 (Starter odloty) | X20: 181 (Bestseller) | Y20: 182 (Zoom palarnia) | Z20: 183 (LMDL) | AA20: 187 (Zoom NS) | AB20: 208 (PIZZA) | AC20: 532 (Magazyn) | AD20: Wszystkie lokale | AJ20: {=IF($C20="","",IFERROR(TRANSPOSE(_xlfn._xlws.FILTER(Listy!$D$2:$D$60,Listy!$C$2:$C$60=$C20)),""))} -> Elektryczny (roczny) | AK20: Elektryczny (5-cio letni) | AL20: Systemy PPOŻ | AM20: Gaśnice | AN20: Klimatyzacja | AO20: Alarmy | AP20: Hydranty | AQ20: Rolety | AR20: Wentylacja | AS20: Wymiana filtrów | AT20: Regałów magazynowych | AU20: CRO | AV20: Mroźnia/Chłodnia | AW20: Regały chłodnicze | AX20: Separatory tłuszczu | AY20: Vendingi | AZ20: UDT (wózki widłowe, paleciaki) | BA20: BHP (drabiny, schodki, podesty) | BB20: Ansul | BC20: Okap | BD20: Brama garażowa | BE20: Żaluzje (gastro) | BF20: Bramki antykradzieżowe | BG20: Mycie jednostek klimatyzacji
A21: WARSZAWA | B21: 208 (PIZZA) | C21: Główny | D21: Elektryczny (5-cio letni) | E21: 45432 | F21: 60 | G21: =IF(OR(E21="",F21=""),"",DATE(YEAR(E21),MONTH(E21)+F21,DAY(E21))) -> 47258 | H21: =IF(G21="","",IF(G21<TODAY(),"PO TERMINIE",IF(G21<=TODAY()+14,"DO WYKONANIA","OK"))) -> OK | J21: =IF(COUNTA(A21:F183)=0,"",IF(#REF!="","BRAK PROTOKOŁU","DODANY")) -> #REF! | M21: {=IF($A21="","",IFERROR(TRANSPOSE(_xlfn._xlws.FILTER(Lokale!$C$3:$C$91,Lokale!$B$3:$B$91=$A21)),""))} -> 170 (Glamour) | N21: 171 (Starter Dworzec) | O21: 172 (Starter Przyloty) | P21: 173 (LMDL2) | Q21: 174 (Zoom NS) | R21: 175 (Ministore NS) | S21: 176 (Zoom odloty) | T21: 177 (Spirit of Poland) | U21: 178 (Multistore) | V21: 179 (ZOOM) | W21: 180 (Starter odloty) | X21: 181 (Bestseller) | Y21: 182 (Zoom palarnia) | Z21: 183 (LMDL) | AA21: 187 (Zoom NS) | AB21: 208 (PIZZA) | AC21: 532 (Magazyn) | AD21: Wszystkie lokale | AJ21: {=IF($C21="","",IFERROR(TRANSPOSE(_xlfn._xlws.FILTER(Listy!$D$2:$D$60,Listy!$C$2:$C$60=$C21)),""))} -> Elektryczny (roczny) | AK21: Elektryczny (5-cio letni) | AL21: Systemy PPOŻ | AM21: Gaśnice | AN21: Klimatyzacja | AO21: Alarmy | AP21: Hydranty | AQ21: Rolety | AR21: Wentylacja | AS21: Wymiana filtrów | AT21: Regałów magazynowych | AU21: CRO | AV21: Mroźnia/Chłodnia | AW21: Regały chłodnicze | AX21: Separatory tłuszczu | AY21: Vendingi | AZ21: UDT (wózki widłowe, paleciaki) | BA21: BHP (drabiny, schodki, podesty) | BB21: Ansul | BC21: Okap | BD21: Brama garażowa | BE21: Żaluzje (gastro) | BF21: Bramki antykradzieżowe | BG21: Mycie jednostek klimatyzacji
A22: WARSZAWA | B22: 208 (PIZZA) | C22: Główny | D22: Wentylacja | E22: 46213 | F22: 12 | G22: =IF(OR(E22="",F22=""),"",DATE(YEAR(E22),MONTH(E22)+F22,DAY(E22))) -> 46578 | H22: =IF(G22="","",IF(G22<TODAY(),"PO TERMINIE",IF(G22<=TODAY()+14,"DO WYKONANIA","OK"))) -> OK | J22: =IF(COUNTA(A22:F183)=0,"",IF(#REF!="","BRAK PROTOKOŁU","DODANY")) -> #REF! | M22: {=IF($A22="","",IFERROR(TRANSPOSE(_xlfn._xlws.FILTER(Lokale!$C$3:$C$91,Lokale!$B$3:$B$91=$A22)),""))} -> 170 (Glamour) | N22: 171 (Starter Dworzec) | O22: 172 (Starter Przyloty) | P22: 173 (LMDL2) | Q22: 174 (Zoom NS) | R22: 175 (Ministore NS) | S22: 176 (Zoom odloty) | T22: 177 (Spirit of Poland) | U22: 178 (Multistore) | V22: 179 (ZOOM) | W22: 180 (Starter odloty) | X22: 181 (Bestseller) | Y22: 182 (Zoom palarnia) | Z22: 183 (LMDL) | AA22: 187 (Zoom NS) | AB22: 208 (PIZZA) | AC22: 532 (Magazyn) | AD22: Wszystkie lokale | AJ22: {=IF($C22="","",IFERROR(TRANSPOSE(_xlfn._xlws.FILTER(Listy!$D$2:$D$60,Listy!$C$2:$C$60=$C22)),""))} -> Elektryczny (roczny) | AK22: Elektryczny (5-cio letni) | AL22: Systemy PPOŻ | AM22: Gaśnice | AN22: Klimatyzacja | AO22: Alarmy | AP22: Hydranty | AQ22: Rolety | AR22: Wentylacja | AS22: Wymiana filtrów | AT22: Regałów magazynowych | AU22: CRO | AV22: Mroźnia/Chłodnia | AW22: Regały chłodnicze | AX22: Separatory tłuszczu | AY22: Vendingi | AZ22: UDT (wózki widłowe, paleciaki) | BA22: BHP (drabiny, schodki, podesty) | BB22: Ansul | BC22: Okap | BD22: Brama garażowa | BE22: Żaluzje (gastro) | BF22: Bramki antykradzieżowe | BG22: Mycie jednostek klimatyzacji
A23: WARSZAWA | B23: 208 (PIZZA) | C23: Główny | D23: Rolety | E23: 45870 | F23: 12 | G23: =IF(OR(E23="",F23=""),"",DATE(YEAR(E23),MONTH(E23)+F23,DAY(E23))) -> 46235 | H23: =IF(G23="","",IF(G23<TODAY(),"PO TERMINIE",IF(G23<=TODAY()+14,"DO WYKONANIA","OK"))) -> DO WYKONANIA | J23: =IF(COUNTA(A23:F183)=0,"",IF(#REF!="","BRAK PROTOKOŁU","DODANY")) -> #REF! | M23: {=IF($A23="","",IFERROR(TRANSPOSE(_xlfn._xlws.FILTER(Lokale!$C$3:$C$91,Lokale!$B$3:$B$91=$A23)),""))} -> 170 (Glamour) | N23: 171 (Starter Dworzec) | O23: 172 (Starter Przyloty) | P23: 173 (LMDL2) | Q23: 174 (Zoom NS) | R23: 175 (Ministore NS) | S23: 176 (Zoom odloty) | T23: 177 (Spirit of Poland) | U23: 178 (Multistore) | V23: 179 (ZOOM) | W23: 180 (Starter odloty) | X23: 181 (Bestseller) | Y23: 182 (Zoom palarnia) | Z23: 183 (LMDL) | AA23: 187 (Zoom NS) | AB23: 208 (PIZZA) | AC23: 532 (Magazyn) | AD23: Wszystkie lokale | AJ23: {=IF($C23="","",IFERROR(TRANSPOSE(_xlfn._xlws.FILTER(Listy!$D$2:$D$60,Listy!$C$2:$C$60=$C23)),""))} -> Elektryczny (roczny) | AK23: Elektryczny (5-cio letni) | AL23: Systemy PPOŻ | AM23: Gaśnice | AN23: Klimatyzacja | AO23: Alarmy | AP23: Hydranty | AQ23: Rolety | AR23: Wentylacja | AS23: Wymiana filtrów | AT23: Regałów magazynowych | AU23: CRO | AV23: Mroźnia/Chłodnia | AW23: Regały chłodnicze | AX23: Separatory tłuszczu | AY23: Vendingi | AZ23: UDT (wózki widłowe, paleciaki) | BA23: BHP (drabiny, schodki, podesty) | BB23: Ansul | BC23: Okap | BD23: Brama garażowa | BE23: Żaluzje (gastro) | BF23: Bramki antykradzieżowe | BG23: Mycie jednostek klimatyzacji
A24: WARSZAWA | B24: 208 (PIZZA) | C24: Główny | D24: Gaśnice | E24: 46054 | F24: 12 | G24: =IF(OR(E24="",F24=""),"",DATE(YEAR(E24),MONTH(E24)+F24,DAY(E24))) -> 46419 | H24: =IF(G24="","",IF(G24<TODAY(),"PO TERMINIE",IF(G24<=TODAY()+14,"DO WYKONANIA","OK"))) -> OK | J24: =IF(COUNTA(A24:F183)=0,"",IF(#REF!="","BRAK PROTOKOŁU","DODANY")) -> #REF! | M24: {=IF($A24="","",IFERROR(TRANSPOSE(_xlfn._xlws.FILTER(Lokale!$C$3:$C$91,Lokale!$B$3:$B$91=$A24)),""))} -> 170 (Glamour) | N24: 171 (Starter Dworzec) | O24: 172 (Starter Przyloty) | P24: 173 (LMDL2) | Q24: 174 (Zoom NS) | R24: 175 (Ministore NS) | S24: 176 (Zoom odloty) | T24: 177 (Spirit of Poland) | U24: 178 (Multistore) | V24: 179 (ZOOM) | W24: 180 (Starter odloty) | X24: 181 (Bestseller) | Y24: 182 (Zoom palarnia) | Z24: 183 (LMDL) | AA24: 187 (Zoom NS) | AB24: 208 (PIZZA) | AC24: 532 (Magazyn) | AD24: Wszystkie lokale | AJ24: {=IF($C24="","",IFERROR(TRANSPOSE(_xlfn._xlws.FILTER(Listy!$D$2:$D$60,Listy!$C$2:$C$60=$C24)),""))} -> Elektryczny (roczny) | AK24: Elektryczny (5-cio letni) | AL24: Systemy PPOŻ | AM24: Gaśnice | AN24: Klimatyzacja | AO24: Alarmy | AP24: Hydranty | AQ24: Rolety | AR24: Wentylacja | AS24: Wymiana filtrów | AT24: Regałów magazynowych | AU24: CRO | AV24: Mroźnia/Chłodnia | AW24: Regały chłodnicze | AX24: Separatory tłuszczu | AY24: Vendingi | AZ24: UDT (wózki widłowe, paleciaki) | BA24: BHP (drabiny, schodki, podesty) | BB24: Ansul | BC24: Okap | BD24: Brama garażowa | BE24: Żaluzje (gastro) | BF24: Bramki antykradzieżowe | BG24: Mycie jednostek klimatyzacji
A25: WARSZAWA | B25: 208 (PIZZA) | C25: Poboczny | D25: Sprawdzenie pompy odpływowej | E25: 46204 | F25: 2 | G25: =IF(OR(E25="",F25=""),"",DATE(YEAR(E25),MONTH(E25)+F25,DAY(E25))) -> 46266 | H25: =IF(G25="","",IF(G25<TODAY(),"PO TERMINIE",IF(G25<=TODAY()+14,"DO WYKONANIA","OK"))) -> OK | J25: =IF(COUNTA(A25:F183)=0,"",IF(#REF!="","BRAK PROTOKOŁU","DODANY")) -> #REF! | M25: {=IF($A25="","",IFERROR(TRANSPOSE(_xlfn._xlws.FILTER(Lokale!$C$3:$C$91,Lokale!$B$3:$B$91=$A25)),""))} -> 170 (Glamour) | N25: 171 (Starter Dworzec) | O25: 172 (Starter Przyloty) | P25: 173 (LMDL2) | Q25: 174 (Zoom NS) | R25: 175 (Ministore NS) | S25: 176 (Zoom odloty) | T25: 177 (Spirit of Poland) | U25: 178 (Multistore) | V25: 179 (ZOOM) | W25: 180 (Starter odloty) | X25: 181 (Bestseller) | Y25: 182 (Zoom palarnia) | Z25: 183 (LMDL) | AA25: 187 (Zoom NS) | AB25: 208 (PIZZA) | AC25: 532 (Magazyn) | AD25: Wszystkie lokale | AJ25: {=IF($C25="","",IFERROR(TRANSPOSE(_xlfn._xlws.FILTER(Listy!$D$2:$D$60,Listy!$C$2:$C$60=$C25)),""))} -> Klamki na kod | AK25: Oświetlenie | AL25: Drzwi przeciwpożarowe | AM25: Drzwi na zaplecze | AN25: Systemy multmedialne | AO25: Posadzki, wykładziny | AP25: Kontrola kurzu | AQ25: Light boxy | AR25: Floorboxy | AS25: Meble | AT25: Szyby | AU25: Lampy owadobójcze | AV25: Samochody | AW25: Windy w samochodach | AX25: Sprawdzenie pompy odpływowej
A26: WARSZAWA | B26: 208 (PIZZA) | C26: Poboczny | D26: Oświetlenie | E26: 46204 | F26: 1 | G26: =IF(OR(E26="",F26=""),"",DATE(YEAR(E26),MONTH(E26)+F26,DAY(E26))) -> 46235 | H26: =IF(G26="","",IF(G26<TODAY(),"PO TERMINIE",IF(G26<=TODAY()+14,"DO WYKONANIA","OK"))) -> DO WYKONANIA | J26: =IF(COUNTA(A26:F183)=0,"",IF(#REF!="","BRAK PROTOKOŁU","DODANY")) -> #REF! | M26: {=IF($A26="","",IFERROR(TRANSPOSE(_xlfn._xlws.FILTER(Lokale!$C$3:$C$91,Lokale!$B$3:$B$91=$A26)),""))} -> 170 (Glamour) | N26: 171 (Starter Dworzec) | O26: 172 (Starter Przyloty) | P26: 173 (LMDL2) | Q26: 174 (Zoom NS) | R26: 175 (Ministore NS) | S26: 176 (Zoom odloty) | T26: 177 (Spirit of Poland) | U26: 178 (Multistore) | V26: 179 (ZOOM) | W26: 180 (Starter odloty) | X26: 181 (Bestseller) | Y26: 182 (Zoom palarnia) | Z26: 183 (LMDL) | AA26: 187 (Zoom NS) | AB26: 208 (PIZZA) | AC26: 532 (Magazyn) | AD26: Wszystkie lokale | AJ26: {=IF($C26="","",IFERROR(TRANSPOSE(_xlfn._xlws.FILTER(Listy!$D$2:$D$60,Listy!$C$2:$C$60=$C26)),""))} -> Klamki na kod | AK26: Oświetlenie | AL26: Drzwi przeciwpożarowe | AM26: Drzwi na zaplecze | AN26: Systemy multmedialne | AO26: Posadzki, wykładziny | AP26: Kontrola kurzu | AQ26: Light boxy | AR26: Floorboxy | AS26: Meble | AT26: Szyby | AU26: Lampy owadobójcze | AV26: Samochody | AW26: Windy w samochodach | AX26: Sprawdzenie pompy odpływowej
G27: =IF(OR(E27="",F27=""),"",DATE(YEAR(E27),MONTH(E27)+F27,DAY(E27))) | H27: =IF(G27="","",IF(G27<TODAY(),"PO TERMINIE",IF(G27<=TODAY()+14,"DO WYKONANIA","OK"))) | J27: =IF(COUNTA(A27:F178)=0,"",IF(#REF!="","BRAK PROTOKOŁU","DODANY")) -> #REF!
A28: WARSZAWA | B28: 177 (Spirit of Poland) | C28: Główny | D28: Elektryczny (roczny) | E28: 46093 | F28: 12 | G28: =IF(OR(E28="",F28=""),"",DATE(YEAR(E28),MONTH(E28)+F28,DAY(E28))) -> 46458 | H28: =IF(G28="","",IF(G28<TODAY(),"PO TERMINIE",IF(G28<=TODAY()+14,"DO WYKONANIA","OK"))) -> OK | J28: =IF(COUNTA(A28:F136)=0,"",IF(#REF!="","BRAK PROTOKOŁU","DODANY")) -> #REF! | M28: {=IF($A28="","",IFERROR(TRANSPOSE(_xlfn._xlws.FILTER(Lokale!$C$3:$C$91,Lokale!$B$3:$B$91=$A28)),""))} -> 170 (Glamour) | N28: 171 (Starter Dworzec) | O28: 172 (Starter Przyloty) | P28: 173 (LMDL2) | Q28: 174 (Zoom NS) | R28: 175 (Ministore NS) | S28: 176 (Zoom odloty) | T28: 177 (Spirit of Poland) | U28: 178 (Multistore) | V28: 179 (ZOOM) | W28: 180 (Starter odloty) | X28: 181 (Bestseller) | Y28: 182 (Zoom palarnia) | Z28: 183 (LMDL) | AA28: 187 (Zoom NS) | AB28: 208 (PIZZA) | AC28: 532 (Magazyn) | AD28: Wszystkie lokale | AJ28: {=IF($C28="","",IFERROR(TRANSPOSE(_xlfn._xlws.FILTER(Listy!$D$2:$D$60,Listy!$C$2:$C$60=$C28)),""))} -> Elektryczny (roczny) | AK28: Elektryczny (5-cio letni) | AL28: Systemy PPOŻ | AM28: Gaśnice | AN28: Klimatyzacja | AO28: Alarmy | AP28: Hydranty | AQ28: Rolety | AR28: Wentylacja | AS28: Wymiana filtrów | AT28: Regałów magazynowych | AU28: CRO | AV28: Mroźnia/Chłodnia | AW28: Regały chłodnicze | AX28: Separatory tłuszczu | AY28: Vendingi | AZ28: UDT (wózki widłowe, paleciaki) | BA28: BHP (drabiny, schodki, podesty) | BB28: Ansul | BC28: Okap | BD28: Brama garażowa | BE28: Żaluzje (gastro) | BF28: Bramki antykradzieżowe | BG28: Mycie jednostek klimatyzacji
A29: WARSZAWA | B29: 177 (Spirit of Poland) | C29: Główny | D29: Elektryczny (5-cio letni) | E29: 44997 | F29: 60 | G29: =IF(OR(E29="",F29=""),"",DATE(YEAR(E29),MONTH(E29)+F29,DAY(E29))) -> 46824 | H29: =IF(G29="","",IF(G29<TODAY(),"PO TERMINIE",IF(G29<=TODAY()+14,"DO WYKONANIA","OK"))) -> OK | J29: =IF(COUNTA(A29:F137)=0,"",IF(#REF!="","BRAK PROTOKOŁU","DODANY")) -> #REF! | M29: {=IF($A29="","",IFERROR(TRANSPOSE(_xlfn._xlws.FILTER(Lokale!$C$3:$C$91,Lokale!$B$3:$B$91=$A29)),""))} -> 170 (Glamour) | N29: 171 (Starter Dworzec) | O29: 172 (Starter Przyloty) | P29: 173 (LMDL2) | Q29: 174 (Zoom NS) | R29: 175 (Ministore NS) | S29: 176 (Zoom odloty) | T29: 177 (Spirit of Poland) | U29: 178 (Multistore) | V29: 179 (ZOOM) | W29: 180 (Starter odloty) | X29: 181 (Bestseller) | Y29: 182 (Zoom palarnia) | Z29: 183 (LMDL) | AA29: 187 (Zoom NS) | AB29: 208 (PIZZA) | AC29: 532 (Magazyn) | AD29: Wszystkie lokale | AJ29: {=IF($C29="","",IFERROR(TRANSPOSE(_xlfn._xlws.FILTER(Listy!$D$2:$D$60,Listy!$C$2:$C$60=$C29)),""))} -> Elektryczny (roczny) | AK29: Elektryczny (5-cio letni) | AL29: Systemy PPOŻ | AM29: Gaśnice | AN29: Klimatyzacja | AO29: Alarmy | AP29: Hydranty | AQ29: Rolety | AR29: Wentylacja | AS29: Wymiana filtrów | AT29: Regałów magazynowych | AU29: CRO | AV29: Mroźnia/Chłodnia | AW29: Regały chłodnicze | AX29: Separatory tłuszczu | AY29: Vendingi | AZ29: UDT (wózki widłowe, paleciaki) | BA29: BHP (drabiny, schodki, podesty) | BB29: Ansul | BC29: Okap | BD29: Brama garażowa | BE29: Żaluzje (gastro) | BF29: Bramki antykradzieżowe | BG29: Mycie jednostek klimatyzacji
A30: WARSZAWA | B30: 177 (Spirit of Poland) | C30: Główny | D30: Gaśnice | E30: 46176 | F30: 12 | G30: =IF(OR(E30="",F30=""),"",DATE(YEAR(E30),MONTH(E30)+F30,DAY(E30))) -> 46541 | H30: =IF(G30="","",IF(G30<TODAY(),"PO TERMINIE",IF(G30<=TODAY()+14,"DO WYKONANIA","OK"))) -> OK | J30: =IF(COUNTA(A30:F139)=0,"",IF(#REF!="","BRAK PROTOKOŁU","DODANY")) -> #REF! | M30: {=IF($A30="","",IFERROR(TRANSPOSE(_xlfn._xlws.FILTER(Lokale!$C$3:$C$91,Lokale!$B$3:$B$91=$A30)),""))} -> 170 (Glamour) | N30: 171 (Starter Dworzec) | O30: 172 (Starter Przyloty) | P30: 173 (LMDL2) | Q30: 174 (Zoom NS) | R30: 175 (Ministore NS) | S30: 176 (Zoom odloty) | T30: 177 (Spirit of Poland) | U30: 178 (Multistore) | V30: 179 (ZOOM) | W30: 180 (Starter odloty) | X30: 181 (Bestseller) | Y30: 182 (Zoom palarnia) | Z30: 183 (LMDL) | AA30: 187 (Zoom NS) | AB30: 208 (PIZZA) | AC30: 532 (Magazyn) | AD30: Wszystkie lokale | AJ30: {=IF($C30="","",IFERROR(TRANSPOSE(_xlfn._xlws.FILTER(Listy!$D$2:$D$60,Listy!$C$2:$C$60=$C30)),""))} -> Elektryczny (roczny) | AK30: Elektryczny (5-cio letni) | AL30: Systemy PPOŻ | AM30: Gaśnice | AN30: Klimatyzacja | AO30: Alarmy | AP30: Hydranty | AQ30: Rolety | AR30: Wentylacja | AS30: Wymiana filtrów | AT30: Regałów magazynowych | AU30: CRO | AV30: Mroźnia/Chłodnia | AW30: Regały chłodnicze | AX30: Separatory tłuszczu | AY30: Vendingi | AZ30: UDT (wózki widłowe, paleciaki) | BA30: BHP (drabiny, schodki, podesty) | BB30: Ansul | BC30: Okap | BD30: Brama garażowa | BE30: Żaluzje (gastro) | BF30: Bramki antykradzieżowe | BG30: Mycie jednostek klimatyzacji
A31: WARSZAWA | B31: 177 (Spirit of Poland) | C31: Główny | D31: Klimatyzacja | E31: 46192 | F31: 3 | G31: =IF(OR(E31="",F31=""),"",DATE(YEAR(E31),MONTH(E31)+F31,DAY(E31))) -> 46284 | H31: =IF(G31="","",IF(G31<TODAY(),"PO TERMINIE",IF(G31<=TODAY()+14,"DO WYKONANIA","OK"))) -> OK | J31: =IF(COUNTA(A31:F140)=0,"",IF(#REF!="","BRAK PROTOKOŁU","DODANY")) -> #REF! | M31: {=IF($A31="","",IFERROR(TRANSPOSE(_xlfn._xlws.FILTER(Lokale!$C$3:$C$91,Lokale!$B$3:$B$91=$A31)),""))} -> 170 (Glamour) | N31: 171 (Starter Dworzec) | O31: 172 (Starter Przyloty) | P31: 173 (LMDL2) | Q31: 174 (Zoom NS) | R31: 175 (Ministore NS) | S31: 176 (Zoom odloty) | T31: 177 (Spirit of Poland) | U31: 178 (Multistore) | V31: 179 (ZOOM) | W31: 180 (Starter odloty) | X31: 181 (Bestseller) | Y31: 182 (Zoom palarnia) | Z31: 183 (LMDL) | AA31: 187 (Zoom NS) | AB31: 208 (PIZZA) | AC31: 532 (Magazyn) | AD31: Wszystkie lokale | AJ31: {=IF($C31="","",IFERROR(TRANSPOSE(_xlfn._xlws.FILTER(Listy!$D$2:$D$60,Listy!$C$2:$C$60=$C31)),""))} -> Elektryczny (roczny) | AK31: Elektryczny (5-cio letni) | AL31: Systemy PPOŻ | AM31: Gaśnice | AN31: Klimatyzacja | AO31: Alarmy | AP31: Hydranty | AQ31: Rolety | AR31: Wentylacja | AS31: Wymiana filtrów | AT31: Regałów magazynowych | AU31: CRO | AV31: Mroźnia/Chłodnia | AW31: Regały chłodnicze | AX31: Separatory tłuszczu | AY31: Vendingi | AZ31: UDT (wózki widłowe, paleciaki) | BA31: BHP (drabiny, schodki, podesty) | BB31: Ansul | BC31: Okap | BD31: Brama garażowa | BE31: Żaluzje (gastro) | BF31: Bramki antykradzieżowe | BG31: Mycie jednostek klimatyzacji
A32: WARSZAWA | B32: 177 (Spirit of Poland) | C32: Główny | D32: Rolety | E32: 46023 | F32: 12 | G32: =IF(OR(E32="",F32=""),"",DATE(YEAR(E32),MONTH(E32)+F32,DAY(E32))) -> 46388 | H32: =IF(G32="","",IF(G32<TODAY(),"PO TERMINIE",IF(G32<=TODAY()+14,"DO WYKONANIA","OK"))) -> OK | J32: =IF(COUNTA(A32:F142)=0,"",IF(#REF!="","BRAK PROTOKOŁU","DODANY")) -> #REF! | M32: {=IF($A32="","",IFERROR(TRANSPOSE(_xlfn._xlws.FILTER(Lokale!$C$3:$C$91,Lokale!$B$3:$B$91=$A32)),""))} -> 170 (Glamour) | N32: 171 (Starter Dworzec) | O32: 172 (Starter Przyloty) | P32: 173 (LMDL2) | Q32: 174 (Zoom NS) | R32: 175 (Ministore NS) | S32: 176 (Zoom odloty) | T32: 177 (Spirit of Poland) | U32: 178 (Multistore) | V32: 179 (ZOOM) | W32: 180 (Starter odloty) | X32: 181 (Bestseller) | Y32: 182 (Zoom palarnia) | Z32: 183 (LMDL) | AA32: 187 (Zoom NS) | AB32: 208 (PIZZA) | AC32: 532 (Magazyn) | AD32: Wszystkie lokale | AJ32: {=IF($C32="","",IFERROR(TRANSPOSE(_xlfn._xlws.FILTER(Listy!$D$2:$D$60,Listy!$C$2:$C$60=$C32)),""))} -> Elektryczny (roczny) | AK32: Elektryczny (5-cio letni) | AL32: Systemy PPOŻ | AM32: Gaśnice | AN32: Klimatyzacja | AO32: Alarmy | AP32: Hydranty | AQ32: Rolety | AR32: Wentylacja | AS32: Wymiana filtrów | AT32: Regałów magazynowych | AU32: CRO | AV32: Mroźnia/Chłodnia | AW32: Regały chłodnicze | AX32: Separatory tłuszczu | AY32: Vendingi | AZ32: UDT (wózki widłowe, paleciaki) | BA32: BHP (drabiny, schodki, podesty) | BB32: Ansul | BC32: Okap | BD32: Brama garażowa | BE32: Żaluzje (gastro) | BF32: Bramki antykradzieżowe | BG32: Mycie jednostek klimatyzacji
A33: WARSZAWA | B33: 177 (Spirit of Poland) | C33: Główny | D33: Wentylacja | E33: 46192 | F33: 12 | G33: =IF(OR(E33="",F33=""),"",DATE(YEAR(E33),MONTH(E33)+F33,DAY(E33))) -> 46557 | H33: =IF(G33="","",IF(G33<TODAY(),"PO TERMINIE",IF(G33<=TODAY()+14,"DO WYKONANIA","OK"))) -> OK | J33: =IF(COUNTA(A33:F143)=0,"",IF(#REF!="","BRAK PROTOKOŁU","DODANY")) -> #REF! | M33: {=IF($A33="","",IFERROR(TRANSPOSE(_xlfn._xlws.FILTER(Lokale!$C$3:$C$91,Lokale!$B$3:$B$91=$A33)),""))} -> 170 (Glamour) | N33: 171 (Starter Dworzec) | O33: 172 (Starter Przyloty) | P33: 173 (LMDL2) | Q33: 174 (Zoom NS) | R33: 175 (Ministore NS) | S33: 176 (Zoom odloty) | T33: 177 (Spirit of Poland) | U33: 178 (Multistore) | V33: 179 (ZOOM) | W33: 180 (Starter odloty) | X33: 181 (Bestseller) | Y33: 182 (Zoom palarnia) | Z33: 183 (LMDL) | AA33: 187 (Zoom NS) | AB33: 208 (PIZZA) | AC33: 532 (Magazyn) | AD33: Wszystkie lokale | AJ33: {=IF($C33="","",IFERROR(TRANSPOSE(_xlfn._xlws.FILTER(Listy!$D$2:$D$60,Listy!$C$2:$C$60=$C33)),""))} -> Elektryczny (roczny) | AK33: Elektryczny (5-cio letni) | AL33: Systemy PPOŻ | AM33: Gaśnice | AN33: Klimatyzacja | AO33: Alarmy | AP33: Hydranty | AQ33: Rolety | AR33: Wentylacja | AS33: Wymiana filtrów | AT33: Regałów magazynowych | AU33: CRO | AV33: Mroźnia/Chłodnia | AW33: Regały chłodnicze | AX33: Separatory tłuszczu | AY33: Vendingi | AZ33: UDT (wózki widłowe, paleciaki) | BA33: BHP (drabiny, schodki, podesty) | BB33: Ansul | BC33: Okap | BD33: Brama garażowa | BE33: Żaluzje (gastro) | BF33: Bramki antykradzieżowe | BG33: Mycie jednostek klimatyzacji
A34: WARSZAWA | B34: 177 (Spirit of Poland) | C34: Główny | D34: Wymiana filtrów | E34: 46192 | F34: 12 | G34: =IF(OR(E34="",F34=""),"",DATE(YEAR(E34),MONTH(E34)+F34,DAY(E34))) -> 46557 | H34: =IF(G34="","",IF(G34<TODAY(),"PO TERMINIE",IF(G34<=TODAY()+14,"DO WYKONANIA","OK"))) -> OK | J34: =IF(COUNTA(A34:F170)=0,"",IF(#REF!="","BRAK PROTOKOŁU","DODANY")) -> #REF!
A35: WARSZAWA | B35: 177 (Spirit of Poland) | C35: Poboczny | D35: Oświetlenie | E35: 46204 | F35: 1 | G35: =IF(OR(E35="",F35=""),"",DATE(YEAR(E35),MONTH(E35)+F35,DAY(E35))) -> 46235 | H35: =IF(G35="","",IF(G35<TODAY(),"PO TERMINIE",IF(G35<=TODAY()+14,"DO WYKONANIA","OK"))) -> DO WYKONANIA | J35: =IF(COUNTA(A35:F148)=0,"",IF(#REF!="","BRAK PROTOKOŁU","DODANY")) -> #REF! | M35: {=IF($A35="","",IFERROR(TRANSPOSE(_xlfn._xlws.FILTER(Lokale!$C$3:$C$91,Lokale!$B$3:$B$91=$A35)),""))} -> 170 (Glamour) | N35: 171 (Starter Dworzec) | O35: 172 (Starter Przyloty) | P35: 173 (LMDL2) | Q35: 174 (Zoom NS) | R35: 175 (Ministore NS) | S35: 176 (Zoom odloty) | T35: 177 (Spirit of Poland) | U35: 178 (Multistore) | V35: 179 (ZOOM) | W35: 180 (Starter odloty) | X35: 181 (Bestseller) | Y35: 182 (Zoom palarnia) | Z35: 183 (LMDL) | AA35: 187 (Zoom NS) | AB35: 208 (PIZZA) | AC35: 532 (Magazyn) | AD35: Wszystkie lokale | AJ35: {=IF($C35="","",IFERROR(TRANSPOSE(_xlfn._xlws.FILTER(Listy!$D$2:$D$60,Listy!$C$2:$C$60=$C35)),""))} -> Klamki na kod | AK35: Oświetlenie | AL35: Drzwi przeciwpożarowe | AM35: Drzwi na zaplecze | AN35: Systemy multmedialne | AO35: Posadzki, wykładziny | AP35: Kontrola kurzu | AQ35: Light boxy | AR35: Floorboxy | AS35: Meble | AT35: Szyby | AU35: Lampy owadobójcze | AV35: Samochody | AW35: Windy w samochodach | AX35: Sprawdzenie pompy odpływowej
A36: WARSZAWA | B36: 177 (Spirit of Poland) | C36: Główny | D36: Mycie jednostek klimatyzacji | E36: 46192 | F36: 36 | G36: =IF(OR(E36="",F36=""),"",DATE(YEAR(E36),MONTH(E36)+F36,DAY(E36))) -> 47288 | H36: =IF(G36="","",IF(G36<TODAY(),"PO TERMINIE",IF(G36<=TODAY()+14,"DO WYKONANIA","OK"))) -> OK | J36: =IF(COUNTA(A36:F156)=0,"",IF(#REF!="","BRAK PROTOKOŁU","DODANY")) -> #REF! | M36: {=IF($A36="","",IFERROR(TRANSPOSE(_xlfn._xlws.FILTER(Lokale!$C$3:$C$91,Lokale!$B$3:$B$91=$A36)),""))} -> 170 (Glamour) | N36: 171 (Starter Dworzec) | O36: 172 (Starter Przyloty) | P36: 173 (LMDL2) | Q36: 174 (Zoom NS) | R36: 175 (Ministore NS) | S36: 176 (Zoom odloty) | T36: 177 (Spirit of Poland) | U36: 178 (Multistore) | V36: 179 (ZOOM) | W36: 180 (Starter odloty) | X36: 181 (Bestseller) | Y36: 182 (Zoom palarnia) | Z36: 183 (LMDL) | AA36: 187 (Zoom NS) | AB36: 208 (PIZZA) | AC36: 532 (Magazyn) | AD36: Wszystkie lokale | AJ36: {=IF($C36="","",IFERROR(TRANSPOSE(_xlfn._xlws.FILTER(Listy!$D$2:$D$60,Listy!$C$2:$C$60=$C36)),""))} -> Elektryczny (roczny) | AK36: Elektryczny (5-cio letni) | AL36: Systemy PPOŻ | AM36: Gaśnice | AN36: Klimatyzacja | AO36: Alarmy | AP36: Hydranty | AQ36: Rolety | AR36: Wentylacja | AS36: Wymiana filtrów | AT36: Regałów magazynowych | AU36: CRO | AV36: Mroźnia/Chłodnia | AW36: Regały chłodnicze | AX36: Separatory tłuszczu | AY36: Vendingi | AZ36: UDT (wózki widłowe, paleciaki) | BA36: BHP (drabiny, schodki, podesty) | BB36: Ansul | BC36: Okap | BD36: Brama garażowa | BE36: Żaluzje (gastro) | BF36: Bramki antykradzieżowe | BG36: Mycie jednostek klimatyzacji
G37: =IF(OR(E37="",F37=""),"",DATE(YEAR(E37),MONTH(E37)+F37,DAY(E37))) | H37: =IF(G37="","",IF(G37<TODAY(),"PO TERMINIE",IF(G37<=TODAY()+14,"DO WYKONANIA","OK"))) | J37: =IF(COUNTA(A37:F179)=0,"",IF(#REF!="","BRAK PROTOKOŁU","DODANY")) -> #REF!
A38: WARSZAWA | B38: 170 (Glamour) | C38: Główny | D38: Elektryczny (roczny) | G38: =IF(OR(E38="",F38=""),"",DATE(YEAR(E38),MONTH(E38)+F38,DAY(E38))) | H38: =IF(G38="","",IF(G38<TODAY(),"PO TERMINIE",IF(G38<=TODAY()+14,"DO WYKONANIA","OK"))) | J38: =IF(COUNTA(A38:F38)=0,"",IF(I38="","BRAK PROTOKOŁU","DODANY")) -> BRAK PROTOKOŁU | M38: {=IF($A38="","",IFERROR(TRANSPOSE(_xlfn._xlws.FILTER(Lokale!$C$3:$C$91,Lokale!$B$3:$B$91=$A38)),""))} -> 170 (Glamour) | N38: 171 (Starter Dworzec) | O38: 172 (Starter Przyloty) | P38: 173 (LMDL2) | Q38: 174 (Zoom NS) | R38: 175 (Ministore NS) | S38: 176 (Zoom odloty) | T38: 177 (Spirit of Poland) | U38: 178 (Multistore) | V38: 179 (ZOOM) | W38: 180 (Starter odloty) | X38: 181 (Bestseller) | Y38: 182 (Zoom palarnia) | Z38: 183 (LMDL) | AA38: 187 (Zoom NS) | AB38: 208 (PIZZA) | AC38: 532 (Magazyn) | AD38: Wszystkie lokale | AJ38: {=IF($C38="","",IFERROR(TRANSPOSE(_xlfn._xlws.FILTER(Listy!$D$2:$D$60,Listy!$C$2:$C$60=$C38)),""))} -> Elektryczny (roczny) | AK38: Elektryczny (5-cio letni) | AL38: Systemy PPOŻ | AM38: Gaśnice | AN38: Klimatyzacja | AO38: Alarmy | AP38: Hydranty | AQ38: Rolety | AR38: Wentylacja | AS38: Wymiana filtrów | AT38: Regałów magazynowych | AU38: CRO | AV38: Mroźnia/Chłodnia | AW38: Regały chłodnicze | AX38: Separatory tłuszczu | AY38: Vendingi | AZ38: UDT (wózki widłowe, paleciaki) | BA38: BHP (drabiny, schodki, podesty) | BB38: Ansul | BC38: Okap | BD38: Brama garażowa | BE38: Żaluzje (gastro) | BF38: Bramki antykradzieżowe | BG38: Mycie jednostek klimatyzacji
A39: WARSZAWA | B39: 170 (Glamour) | C39: Główny | D39: Elektryczny (5-cio letni) | G39: =IF(OR(E39="",F39=""),"",DATE(YEAR(E39),MONTH(E39)+F39,DAY(E39))) | H39: =IF(G39="","",IF(G39<TODAY(),"PO TERMINIE",IF(G39<=TODAY()+14,"DO WYKONANIA","OK"))) | J39: =IF(COUNTA(A39:F39)=0,"",IF(I39="","BRAK PROTOKOŁU","DODANY")) -> BRAK PROTOKOŁU | M39: {=IF($A39="","",IFERROR(TRANSPOSE(_xlfn._xlws.FILTER(Lokale!$C$3:$C$91,Lokale!$B$3:$B$91=$A39)),""))} -> 170 (Glamour) | N39: 171 (Starter Dworzec) | O39: 172 (Starter Przyloty) | P39: 173 (LMDL2) | Q39: 174 (Zoom NS) | R39: 175 (Ministore NS) | S39: 176 (Zoom odloty) | T39: 177 (Spirit of Poland) | U39: 178 (Multistore) | V39: 179 (ZOOM) | W39: 180 (Starter odloty) | X39: 181 (Bestseller) | Y39: 182 (Zoom palarnia) | Z39: 183 (LMDL) | AA39: 187 (Zoom NS) | AB39: 208 (PIZZA) | AC39: 532 (Magazyn) | AD39: Wszystkie lokale | AJ39: {=IF($C39="","",IFERROR(TRANSPOSE(_xlfn._xlws.FILTER(Listy!$D$2:$D$60,Listy!$C$2:$C$60=$C39)),""))} -> Elektryczny (roczny) | AK39: Elektryczny (5-cio letni) | AL39: Systemy PPOŻ | AM39: Gaśnice | AN39: Klimatyzacja | AO39: Alarmy | AP39: Hydranty | AQ39: Rolety | AR39: Wentylacja | AS39: Wymiana filtrów | AT39: Regałów magazynowych | AU39: CRO | AV39: Mroźnia/Chłodnia | AW39: Regały chłodnicze | AX39: Separatory tłuszczu | AY39: Vendingi | AZ39: UDT (wózki widłowe, paleciaki) | BA39: BHP (drabiny, schodki, podesty) | BB39: Ansul | BC39: Okap | BD39: Brama garażowa | BE39: Żaluzje (gastro) | BF39: Bramki antykradzieżowe | BG39: Mycie jednostek klimatyzacji
A40: WARSZAWA | B40: 170 (Glamour) | C40: Główny | D40: Systemy PPOŻ | G40: =IF(OR(E40="",F40=""),"",DATE(YEAR(E40),MONTH(E40)+F40,DAY(E40))) | H40: =IF(G40="","",IF(G40<TODAY(),"PO TERMINIE",IF(G40<=TODAY()+14,"DO WYKONANIA","OK"))) | J40: =IF(COUNTA(A40:F40)=0,"",IF(I40="","BRAK PROTOKOŁU","DODANY")) -> BRAK PROTOKOŁU | M40: {=IF($A40="","",IFERROR(TRANSPOSE(_xlfn._xlws.FILTER(Lokale!$C$3:$C$91,Lokale!$B$3:$B$91=$A40)),""))} -> 170 (Glamour) | N40: 171 (Starter Dworzec) | O40: 172 (Starter Przyloty) | P40: 173 (LMDL2) | Q40: 174 (Zoom NS) | R40: 175 (Ministore NS) | S40: 176 (Zoom odloty) | T40: 177 (Spirit of Poland) | U40: 178 (Multistore) | V40: 179 (ZOOM) | W40: 180 (Starter odloty) | X40: 181 (Bestseller) | Y40: 182 (Zoom palarnia) | Z40: 183 (LMDL) | AA40: 187 (Zoom NS) | AB40: 208 (PIZZA) | AC40: 532 (Magazyn) | AD40: Wszystkie lokale | AJ40: {=IF($C40="","",IFERROR(TRANSPOSE(_xlfn._xlws.FILTER(Listy!$D$2:$D$60,Listy!$C$2:$C$60=$C40)),""))} -> Elektryczny (roczny) | AK40: Elektryczny (5-cio letni) | AL40: Systemy PPOŻ | AM40: Gaśnice | AN40: Klimatyzacja | AO40: Alarmy | AP40: Hydranty | AQ40: Rolety | AR40: Wentylacja | AS40: Wymiana filtrów | AT40: Regałów magazynowych | AU40: CRO | AV40: Mroźnia/Chłodnia | AW40: Regały chłodnicze | AX40: Separatory tłuszczu | AY40: Vendingi | AZ40: UDT (wózki widłowe, paleciaki) | BA40: BHP (drabiny, schodki, podesty) | BB40: Ansul | BC40: Okap | BD40: Brama garażowa | BE40: Żaluzje (gastro) | BF40: Bramki antykradzieżowe | BG40: Mycie jednostek klimatyzacji
...
